Exception while resolving variable 'cart_items' in template 'home.html'.
Traceback (most recent call last):
  File "/home/ubuntu/stringkeeper/lib/python3.8/site-packages/django/template/base.py", line 829, in _resolve_lookup
    current = current[bit]
  File "/home/ubuntu/stringkeeper/lib/python3.8/site-packages/django/contrib/sessions/backends/base.py", line 54, in __getitem__
    return self._session[key]
KeyError: 'cart_items'

During handling of the above exception, another exception occurred:

Traceback (most recent call last):
  File "/home/ubuntu/stringkeeper/lib/python3.8/site-packages/django/template/base.py", line 837, in _resolve_lookup
    current = getattr(current, bit)
AttributeError: 'SessionStore' object has no attribute 'cart_items'

During handling of the above exception, another exception occurred:

Traceback (most recent call last):
  File "/home/ubuntu/stringkeeper/lib/python3.8/site-packages/django/template/base.py", line 843, in _resolve_lookup
    current = current[int(bit)]
ValueError: invalid literal for int() with base 10: 'cart_items'

During handling of the above exception, another exception occurred:

Traceback (most recent call last):
  File "/home/ubuntu/stringkeeper/lib/python3.8/site-packages/django/template/base.py", line 848, in _resolve_lookup
    raise VariableDoesNotExist("Failed lookup for key "
django.template.base.VariableDoesNotExist: Failed lookup for key [cart_items] in <django.contrib.sessions.backends.db.SessionStore object at 0x7fa35fb65760>
Exception while resolving variable 'q' in template 'home.html'.
Traceback (most recent call last):
  File "/home/ubuntu/stringkeeper/lib/python3.8/site-packages/django/utils/datastructures.py", line 78, in __getitem__
    list_ = super().__getitem__(key)
KeyError: 'q'

During handling of the above exception, another exception occurred:

Traceback (most recent call last):
  File "/home/ubuntu/stringkeeper/lib/python3.8/site-packages/django/template/base.py", line 829, in _resolve_lookup
    current = current[bit]
  File "/home/ubuntu/stringkeeper/lib/python3.8/site-packages/django/utils/datastructures.py", line 80, in __getitem__
    raise MultiValueDictKeyError(key)
django.utils.datastructures.MultiValueDictKeyError: 'q'

During handling of the above exception, another exception occurred:

Traceback (most recent call last):
  File "/home/ubuntu/stringkeeper/lib/python3.8/site-packages/django/template/base.py", line 837, in _resolve_lookup
    current = getattr(current, bit)
AttributeError: 'QueryDict' object has no attribute 'q'

During handling of the above exception, another exception occurred:

Traceback (most recent call last):
  File "/home/ubuntu/stringkeeper/lib/python3.8/site-packages/django/template/base.py", line 843, in _resolve_lookup
    current = current[int(bit)]
ValueError: invalid literal for int() with base 10: 'q'

During handling of the above exception, another exception occurred:

Traceback (most recent call last):
  File "/home/ubuntu/stringkeeper/lib/python3.8/site-packages/django/template/base.py", line 848, in _resolve_lookup
    raise VariableDoesNotExist("Failed lookup for key "
django.template.base.VariableDoesNotExist: Failed lookup for key [q] in <QueryDict: {}>
Method Not Allowed (GET): /webhooks/mailchimp/
Method Not Allowed: /webhooks/mailchimp/
Method Not Allowed (GET): /webhooks/mailchimp/
Method Not Allowed: /webhooks/mailchimp/
Exception while resolving variable 'cart_items' in template 'home.html'.
Traceback (most recent call last):
  File "/home/ubuntu/stringkeeper/lib/python3.8/site-packages/django/template/base.py", line 829, in _resolve_lookup
    current = current[bit]
  File "/home/ubuntu/stringkeeper/lib/python3.8/site-packages/django/contrib/sessions/backends/base.py", line 54, in __getitem__
    return self._session[key]
KeyError: 'cart_items'

During handling of the above exception, another exception occurred:

Traceback (most recent call last):
  File "/home/ubuntu/stringkeeper/lib/python3.8/site-packages/django/template/base.py", line 837, in _resolve_lookup
    current = getattr(current, bit)
AttributeError: 'SessionStore' object has no attribute 'cart_items'

During handling of the above exception, another exception occurred:

Traceback (most recent call last):
  File "/home/ubuntu/stringkeeper/lib/python3.8/site-packages/django/template/base.py", line 843, in _resolve_lookup
    current = current[int(bit)]
ValueError: invalid literal for int() with base 10: 'cart_items'

During handling of the above exception, another exception occurred:

Traceback (most recent call last):
  File "/home/ubuntu/stringkeeper/lib/python3.8/site-packages/django/template/base.py", line 848, in _resolve_lookup
    raise VariableDoesNotExist("Failed lookup for key "
django.template.base.VariableDoesNotExist: Failed lookup for key [cart_items] in <django.contrib.sessions.backends.db.SessionStore object at 0x7f894c575610>
Exception while resolving variable 'q' in template 'home.html'.
Traceback (most recent call last):
  File "/home/ubuntu/stringkeeper/lib/python3.8/site-packages/django/utils/datastructures.py", line 78, in __getitem__
    list_ = super().__getitem__(key)
KeyError: 'q'

During handling of the above exception, another exception occurred:

Traceback (most recent call last):
  File "/home/ubuntu/stringkeeper/lib/python3.8/site-packages/django/template/base.py", line 829, in _resolve_lookup
    current = current[bit]
  File "/home/ubuntu/stringkeeper/lib/python3.8/site-packages/django/utils/datastructures.py", line 80, in __getitem__
    raise MultiValueDictKeyError(key)
django.utils.datastructures.MultiValueDictKeyError: 'q'

During handling of the above exception, another exception occurred:

Traceback (most recent call last):
  File "/home/ubuntu/stringkeeper/lib/python3.8/site-packages/django/template/base.py", line 837, in _resolve_lookup
    current = getattr(current, bit)
AttributeError: 'QueryDict' object has no attribute 'q'

During handling of the above exception, another exception occurred:

Traceback (most recent call last):
  File "/home/ubuntu/stringkeeper/lib/python3.8/site-packages/django/template/base.py", line 843, in _resolve_lookup
    current = current[int(bit)]
ValueError: invalid literal for int() with base 10: 'q'

During handling of the above exception, another exception occurred:

Traceback (most recent call last):
  File "/home/ubuntu/stringkeeper/lib/python3.8/site-packages/django/template/base.py", line 848, in _resolve_lookup
    raise VariableDoesNotExist("Failed lookup for key "
django.template.base.VariableDoesNotExist: Failed lookup for key [q] in <QueryDict: {}>
Exception while resolving variable 'cart_items' in template 'subscription/list.html'.
Traceback (most recent call last):
  File "/home/ubuntu/stringkeeper/lib/python3.8/site-packages/django/template/base.py", line 829, in _resolve_lookup
    current = current[bit]
  File "/home/ubuntu/stringkeeper/lib/python3.8/site-packages/django/contrib/sessions/backends/base.py", line 54, in __getitem__
    return self._session[key]
KeyError: 'cart_items'

During handling of the above exception, another exception occurred:

Traceback (most recent call last):
  File "/home/ubuntu/stringkeeper/lib/python3.8/site-packages/django/template/base.py", line 837, in _resolve_lookup
    current = getattr(current, bit)
AttributeError: 'SessionStore' object has no attribute 'cart_items'

During handling of the above exception, another exception occurred:

Traceback (most recent call last):
  File "/home/ubuntu/stringkeeper/lib/python3.8/site-packages/django/template/base.py", line 843, in _resolve_lookup
    current = current[int(bit)]
ValueError: invalid literal for int() with base 10: 'cart_items'

During handling of the above exception, another exception occurred:

Traceback (most recent call last):
  File "/home/ubuntu/stringkeeper/lib/python3.8/site-packages/django/template/base.py", line 848, in _resolve_lookup
    raise VariableDoesNotExist("Failed lookup for key "
django.template.base.VariableDoesNotExist: Failed lookup for key [cart_items] in <django.contrib.sessions.backends.db.SessionStore object at 0x7f894ba7b460>
Exception while resolving variable 'q' in template 'subscription/list.html'.
Traceback (most recent call last):
  File "/home/ubuntu/stringkeeper/lib/python3.8/site-packages/django/utils/datastructures.py", line 78, in __getitem__
    list_ = super().__getitem__(key)
KeyError: 'q'

During handling of the above exception, another exception occurred:

Traceback (most recent call last):
  File "/home/ubuntu/stringkeeper/lib/python3.8/site-packages/django/template/base.py", line 829, in _resolve_lookup
    current = current[bit]
  File "/home/ubuntu/stringkeeper/lib/python3.8/site-packages/django/utils/datastructures.py", line 80, in __getitem__
    raise MultiValueDictKeyError(key)
django.utils.datastructures.MultiValueDictKeyError: 'q'

During handling of the above exception, another exception occurred:

Traceback (most recent call last):
  File "/home/ubuntu/stringkeeper/lib/python3.8/site-packages/django/template/base.py", line 837, in _resolve_lookup
    current = getattr(current, bit)
AttributeError: 'QueryDict' object has no attribute 'q'

During handling of the above exception, another exception occurred:

Traceback (most recent call last):
  File "/home/ubuntu/stringkeeper/lib/python3.8/site-packages/django/template/base.py", line 843, in _resolve_lookup
    current = current[int(bit)]
ValueError: invalid literal for int() with base 10: 'q'

During handling of the above exception, another exception occurred:

Traceback (most recent call last):
  File "/home/ubuntu/stringkeeper/lib/python3.8/site-packages/django/template/base.py", line 848, in _resolve_lookup
    raise VariableDoesNotExist("Failed lookup for key "
django.template.base.VariableDoesNotExist: Failed lookup for key [q] in <QueryDict: {}>
Exception while resolving variable 'ascii_art' in template 'subscription/list.html'.
Traceback (most recent call last):
  File "/home/ubuntu/stringkeeper/lib/python3.8/site-packages/django/template/base.py", line 829, in _resolve_lookup
    current = current[bit]
  File "/home/ubuntu/stringkeeper/lib/python3.8/site-packages/django/template/context.py", line 83, in __getitem__
    raise KeyError(key)
KeyError: 'ascii_art'

During handling of the above exception, another exception occurred:

Traceback (most recent call last):
  File "/home/ubuntu/stringkeeper/lib/python3.8/site-packages/django/template/base.py", line 835, in _resolve_lookup
    if isinstance(current, BaseContext) and getattr(type(current), bit):
AttributeError: type object 'RequestContext' has no attribute 'ascii_art'

During handling of the above exception, another exception occurred:

Traceback (most recent call last):
  File "/home/ubuntu/stringkeeper/lib/python3.8/site-packages/django/template/base.py", line 843, in _resolve_lookup
    current = current[int(bit)]
ValueError: invalid literal for int() with base 10: 'ascii_art'

During handling of the above exception, another exception occurred:

Traceback (most recent call last):
  File "/home/ubuntu/stringkeeper/lib/python3.8/site-packages/django/template/base.py", line 848, in _resolve_lookup
    raise VariableDoesNotExist("Failed lookup for key "
django.template.base.VariableDoesNotExist: Failed lookup for key [ascii_art] in [{'True': True, 'False': False, 'None': None}, {'csrf_token': <SimpleLazyObject: 'e10VJzPn2cfOEuUHU8qCejR9EtW7A7m4LXv8AG9nLUcJCfjKY6eCeuIW6vUbabb2'>, 'request': <WSGIRequest: GET '/subscriptions/'>, 'user': <SimpleLazyObject: <User: andre@stringkeeper.com>>, 'perms': <django.contrib.auth.context_processors.PermWrapper object at 0x7f894a9e1640>, 'messages': <django.contrib.messages.storage.fallback.FallbackStorage object at 0x7f894ba81040>, 'DEFAULT_MESSAGE_LEVELS': {'DEBUG': 10, 'INFO': 20, 'SUCCESS': 25, 'WARNING': 30, 'ERROR': 40}}, {}, {'paginator': None, 'page_obj': None, 'is_paginated': False, 'object_list': <SubscriptionQuerySet [<Subscription: Sint salutatus>, <Subscription: Nibh pericula>, <Subscription: Cu brute>, <Subscription: Ne sit>, <Subscription: Pri vocent>, <Subscription: Eum ridens>, <Subscription: Sensibus ocurreret>]>, 'subscription_list': <SubscriptionQuerySet [<Subscription: Sint salutatus>, <Subscription: Nibh pericula>, <Subscription: Cu brute>, <Subscription: Ne sit>, <Subscription: Pri vocent>, <Subscription: Eum ridens>, <Subscription: Sensibus ocurreret>]>, 'view': <subscription.views.SubscriptionListView object at 0x7f894ba810d0>, 'cart': <Cart: 127>}]
Method Not Allowed (GET): /webhooks/mailchimp/
Method Not Allowed: /webhooks/mailchimp/
