Exception while resolving variable 'cart_items' in template 'home.html'.
Traceback (most recent call last):
  File "/home/ubuntu/stringkeeper/lib/python3.8/site-packages/django/template/base.py", line 829, in _resolve_lookup
    current = current[bit]
  File "/home/ubuntu/stringkeeper/lib/python3.8/site-packages/django/contrib/sessions/backends/base.py", line 54, in __getitem__
    return self._session[key]
KeyError: 'cart_items'

During handling of the above exception, another exception occurred:

Traceback (most recent call last):
  File "/home/ubuntu/stringkeeper/lib/python3.8/site-packages/django/template/base.py", line 837, in _resolve_lookup
    current = getattr(current, bit)
AttributeError: 'SessionStore' object has no attribute 'cart_items'

During handling of the above exception, another exception occurred:

Traceback (most recent call last):
  File "/home/ubuntu/stringkeeper/lib/python3.8/site-packages/django/template/base.py", line 843, in _resolve_lookup
    current = current[int(bit)]
ValueError: invalid literal for int() with base 10: 'cart_items'

During handling of the above exception, another exception occurred:

Traceback (most recent call last):
  File "/home/ubuntu/stringkeeper/lib/python3.8/site-packages/django/template/base.py", line 848, in _resolve_lookup
    raise VariableDoesNotExist("Failed lookup for key "
django.template.base.VariableDoesNotExist: Failed lookup for key [cart_items] in <django.contrib.sessions.backends.db.SessionStore object at 0x7f49149c6af0>
Exception while resolving variable 'q' in template 'home.html'.
Traceback (most recent call last):
  File "/home/ubuntu/stringkeeper/lib/python3.8/site-packages/django/utils/datastructures.py", line 78, in __getitem__
    list_ = super().__getitem__(key)
KeyError: 'q'

During handling of the above exception, another exception occurred:

Traceback (most recent call last):
  File "/home/ubuntu/stringkeeper/lib/python3.8/site-packages/django/template/base.py", line 829, in _resolve_lookup
    current = current[bit]
  File "/home/ubuntu/stringkeeper/lib/python3.8/site-packages/django/utils/datastructures.py", line 80, in __getitem__
    raise MultiValueDictKeyError(key)
django.utils.datastructures.MultiValueDictKeyError: 'q'

During handling of the above exception, another exception occurred:

Traceback (most recent call last):
  File "/home/ubuntu/stringkeeper/lib/python3.8/site-packages/django/template/base.py", line 837, in _resolve_lookup
    current = getattr(current, bit)
AttributeError: 'QueryDict' object has no attribute 'q'

During handling of the above exception, another exception occurred:

Traceback (most recent call last):
  File "/home/ubuntu/stringkeeper/lib/python3.8/site-packages/django/template/base.py", line 843, in _resolve_lookup
    current = current[int(bit)]
ValueError: invalid literal for int() with base 10: 'q'

During handling of the above exception, another exception occurred:

Traceback (most recent call last):
  File "/home/ubuntu/stringkeeper/lib/python3.8/site-packages/django/template/base.py", line 848, in _resolve_lookup
    raise VariableDoesNotExist("Failed lookup for key "
django.template.base.VariableDoesNotExist: Failed lookup for key [q] in <QueryDict: {}>
Exception while resolving variable 'cart_items' in template 'home.html'.
Traceback (most recent call last):
  File "/home/ubuntu/stringkeeper/lib/python3.8/site-packages/django/template/base.py", line 829, in _resolve_lookup
    current = current[bit]
  File "/home/ubuntu/stringkeeper/lib/python3.8/site-packages/django/contrib/sessions/backends/base.py", line 54, in __getitem__
    return self._session[key]
KeyError: 'cart_items'

During handling of the above exception, another exception occurred:

Traceback (most recent call last):
  File "/home/ubuntu/stringkeeper/lib/python3.8/site-packages/django/template/base.py", line 837, in _resolve_lookup
    current = getattr(current, bit)
AttributeError: 'SessionStore' object has no attribute 'cart_items'

During handling of the above exception, another exception occurred:

Traceback (most recent call last):
  File "/home/ubuntu/stringkeeper/lib/python3.8/site-packages/django/template/base.py", line 843, in _resolve_lookup
    current = current[int(bit)]
ValueError: invalid literal for int() with base 10: 'cart_items'

During handling of the above exception, another exception occurred:

Traceback (most recent call last):
  File "/home/ubuntu/stringkeeper/lib/python3.8/site-packages/django/template/base.py", line 848, in _resolve_lookup
    raise VariableDoesNotExist("Failed lookup for key "
django.template.base.VariableDoesNotExist: Failed lookup for key [cart_items] in <django.contrib.sessions.backends.db.SessionStore object at 0x7f4912ba6640>
Exception while resolving variable 'q' in template 'home.html'.
Traceback (most recent call last):
  File "/home/ubuntu/stringkeeper/lib/python3.8/site-packages/django/utils/datastructures.py", line 78, in __getitem__
    list_ = super().__getitem__(key)
KeyError: 'q'

During handling of the above exception, another exception occurred:

Traceback (most recent call last):
  File "/home/ubuntu/stringkeeper/lib/python3.8/site-packages/django/template/base.py", line 829, in _resolve_lookup
    current = current[bit]
  File "/home/ubuntu/stringkeeper/lib/python3.8/site-packages/django/utils/datastructures.py", line 80, in __getitem__
    raise MultiValueDictKeyError(key)
django.utils.datastructures.MultiValueDictKeyError: 'q'

During handling of the above exception, another exception occurred:

Traceback (most recent call last):
  File "/home/ubuntu/stringkeeper/lib/python3.8/site-packages/django/template/base.py", line 837, in _resolve_lookup
    current = getattr(current, bit)
AttributeError: 'QueryDict' object has no attribute 'q'

During handling of the above exception, another exception occurred:

Traceback (most recent call last):
  File "/home/ubuntu/stringkeeper/lib/python3.8/site-packages/django/template/base.py", line 843, in _resolve_lookup
    current = current[int(bit)]
ValueError: invalid literal for int() with base 10: 'q'

During handling of the above exception, another exception occurred:

Traceback (most recent call last):
  File "/home/ubuntu/stringkeeper/lib/python3.8/site-packages/django/template/base.py", line 848, in _resolve_lookup
    raise VariableDoesNotExist("Failed lookup for key "
django.template.base.VariableDoesNotExist: Failed lookup for key [q] in <QueryDict: {}>
Exception while resolving variable 'cart_items' in template 'accounts/register.html'.
Traceback (most recent call last):
  File "/home/ubuntu/stringkeeper/lib/python3.8/site-packages/django/template/base.py", line 829, in _resolve_lookup
    current = current[bit]
  File "/home/ubuntu/stringkeeper/lib/python3.8/site-packages/django/contrib/sessions/backends/base.py", line 54, in __getitem__
    return self._session[key]
KeyError: 'cart_items'

During handling of the above exception, another exception occurred:

Traceback (most recent call last):
  File "/home/ubuntu/stringkeeper/lib/python3.8/site-packages/django/template/base.py", line 837, in _resolve_lookup
    current = getattr(current, bit)
AttributeError: 'SessionStore' object has no attribute 'cart_items'

During handling of the above exception, another exception occurred:

Traceback (most recent call last):
  File "/home/ubuntu/stringkeeper/lib/python3.8/site-packages/django/template/base.py", line 843, in _resolve_lookup
    current = current[int(bit)]
ValueError: invalid literal for int() with base 10: 'cart_items'

During handling of the above exception, another exception occurred:

Traceback (most recent call last):
  File "/home/ubuntu/stringkeeper/lib/python3.8/site-packages/django/template/base.py", line 848, in _resolve_lookup
    raise VariableDoesNotExist("Failed lookup for key "
django.template.base.VariableDoesNotExist: Failed lookup for key [cart_items] in <django.contrib.sessions.backends.db.SessionStore object at 0x7f4912c71310>
Exception while resolving variable 'q' in template 'accounts/register.html'.
Traceback (most recent call last):
  File "/home/ubuntu/stringkeeper/lib/python3.8/site-packages/django/utils/datastructures.py", line 78, in __getitem__
    list_ = super().__getitem__(key)
KeyError: 'q'

During handling of the above exception, another exception occurred:

Traceback (most recent call last):
  File "/home/ubuntu/stringkeeper/lib/python3.8/site-packages/django/template/base.py", line 829, in _resolve_lookup
    current = current[bit]
  File "/home/ubuntu/stringkeeper/lib/python3.8/site-packages/django/utils/datastructures.py", line 80, in __getitem__
    raise MultiValueDictKeyError(key)
django.utils.datastructures.MultiValueDictKeyError: 'q'

During handling of the above exception, another exception occurred:

Traceback (most recent call last):
  File "/home/ubuntu/stringkeeper/lib/python3.8/site-packages/django/template/base.py", line 837, in _resolve_lookup
    current = getattr(current, bit)
AttributeError: 'QueryDict' object has no attribute 'q'

During handling of the above exception, another exception occurred:

Traceback (most recent call last):
  File "/home/ubuntu/stringkeeper/lib/python3.8/site-packages/django/template/base.py", line 843, in _resolve_lookup
    current = current[int(bit)]
ValueError: invalid literal for int() with base 10: 'q'

During handling of the above exception, another exception occurred:

Traceback (most recent call last):
  File "/home/ubuntu/stringkeeper/lib/python3.8/site-packages/django/template/base.py", line 848, in _resolve_lookup
    raise VariableDoesNotExist("Failed lookup for key "
django.template.base.VariableDoesNotExist: Failed lookup for key [q] in <QueryDict: {}>
Exception while resolving variable 'ascii_art' in template 'accounts/register.html'.
Traceback (most recent call last):
  File "/home/ubuntu/stringkeeper/lib/python3.8/site-packages/django/template/base.py", line 829, in _resolve_lookup
    current = current[bit]
  File "/home/ubuntu/stringkeeper/lib/python3.8/site-packages/django/template/context.py", line 83, in __getitem__
    raise KeyError(key)
KeyError: 'ascii_art'

During handling of the above exception, another exception occurred:

Traceback (most recent call last):
  File "/home/ubuntu/stringkeeper/lib/python3.8/site-packages/django/template/base.py", line 835, in _resolve_lookup
    if isinstance(current, BaseContext) and getattr(type(current), bit):
AttributeError: type object 'RequestContext' has no attribute 'ascii_art'

During handling of the above exception, another exception occurred:

Traceback (most recent call last):
  File "/home/ubuntu/stringkeeper/lib/python3.8/site-packages/django/template/base.py", line 843, in _resolve_lookup
    current = current[int(bit)]
ValueError: invalid literal for int() with base 10: 'ascii_art'

During handling of the above exception, another exception occurred:

Traceback (most recent call last):
  File "/home/ubuntu/stringkeeper/lib/python3.8/site-packages/django/template/base.py", line 848, in _resolve_lookup
    raise VariableDoesNotExist("Failed lookup for key "
django.template.base.VariableDoesNotExist: Failed lookup for key [ascii_art] in [{'True': True, 'False': False, 'None': None}, {'csrf_token': <SimpleLazyObject: 's657JlpjWo6l6Ulkg7ZXEPnJf2Lx7Gvi2zerhAQNZfMj834JYQiE0RLlVrV1nWqw'>, 'request': <WSGIRequest: GET '/register/'>, 'user': <SimpleLazyObject: <django.contrib.auth.models.AnonymousUser object at 0x7f4912bd3820>>, 'perms': <django.contrib.auth.context_processors.PermWrapper object at 0x7f4912bb71c0>, 'messages': <django.contrib.messages.storage.fallback.FallbackStorage object at 0x7f4912c715b0>, 'DEFAULT_MESSAGE_LEVELS': {'DEBUG': 10, 'INFO': 20, 'SUCCESS': 25, 'WARNING': 30, 'ERROR': 40}}, {}, {'form': <RegisterForm bound=False, valid=False, fields=(first_name;last_name;email;password1;password2)>, 'view': <accounts.views.RegisterView object at 0x7f4912c71370>}]
Exception while resolving variable 'cart_items' in template 'accounts/login.html'.
Traceback (most recent call last):
  File "/home/ubuntu/stringkeeper/lib/python3.8/site-packages/django/template/base.py", line 829, in _resolve_lookup
    current = current[bit]
  File "/home/ubuntu/stringkeeper/lib/python3.8/site-packages/django/contrib/sessions/backends/base.py", line 54, in __getitem__
    return self._session[key]
KeyError: 'cart_items'

During handling of the above exception, another exception occurred:

Traceback (most recent call last):
  File "/home/ubuntu/stringkeeper/lib/python3.8/site-packages/django/template/base.py", line 837, in _resolve_lookup
    current = getattr(current, bit)
AttributeError: 'SessionStore' object has no attribute 'cart_items'

During handling of the above exception, another exception occurred:

Traceback (most recent call last):
  File "/home/ubuntu/stringkeeper/lib/python3.8/site-packages/django/template/base.py", line 843, in _resolve_lookup
    current = current[int(bit)]
ValueError: invalid literal for int() with base 10: 'cart_items'

During handling of the above exception, another exception occurred:

Traceback (most recent call last):
  File "/home/ubuntu/stringkeeper/lib/python3.8/site-packages/django/template/base.py", line 848, in _resolve_lookup
    raise VariableDoesNotExist("Failed lookup for key "
django.template.base.VariableDoesNotExist: Failed lookup for key [cart_items] in <django.contrib.sessions.backends.db.SessionStore object at 0x7f4912c178e0>
Exception while resolving variable 'q' in template 'accounts/login.html'.
Traceback (most recent call last):
  File "/home/ubuntu/stringkeeper/lib/python3.8/site-packages/django/utils/datastructures.py", line 78, in __getitem__
    list_ = super().__getitem__(key)
KeyError: 'q'

During handling of the above exception, another exception occurred:

Traceback (most recent call last):
  File "/home/ubuntu/stringkeeper/lib/python3.8/site-packages/django/template/base.py", line 829, in _resolve_lookup
    current = current[bit]
  File "/home/ubuntu/stringkeeper/lib/python3.8/site-packages/django/utils/datastructures.py", line 80, in __getitem__
    raise MultiValueDictKeyError(key)
django.utils.datastructures.MultiValueDictKeyError: 'q'

During handling of the above exception, another exception occurred:

Traceback (most recent call last):
  File "/home/ubuntu/stringkeeper/lib/python3.8/site-packages/django/template/base.py", line 837, in _resolve_lookup
    current = getattr(current, bit)
AttributeError: 'QueryDict' object has no attribute 'q'

During handling of the above exception, another exception occurred:

Traceback (most recent call last):
  File "/home/ubuntu/stringkeeper/lib/python3.8/site-packages/django/template/base.py", line 843, in _resolve_lookup
    current = current[int(bit)]
ValueError: invalid literal for int() with base 10: 'q'

During handling of the above exception, another exception occurred:

Traceback (most recent call last):
  File "/home/ubuntu/stringkeeper/lib/python3.8/site-packages/django/template/base.py", line 848, in _resolve_lookup
    raise VariableDoesNotExist("Failed lookup for key "
django.template.base.VariableDoesNotExist: Failed lookup for key [q] in <QueryDict: {}>
Exception while resolving variable 'ascii_art' in template 'accounts/login.html'.
Traceback (most recent call last):
  File "/home/ubuntu/stringkeeper/lib/python3.8/site-packages/django/template/base.py", line 829, in _resolve_lookup
    current = current[bit]
  File "/home/ubuntu/stringkeeper/lib/python3.8/site-packages/django/template/context.py", line 83, in __getitem__
    raise KeyError(key)
KeyError: 'ascii_art'

During handling of the above exception, another exception occurred:

Traceback (most recent call last):
  File "/home/ubuntu/stringkeeper/lib/python3.8/site-packages/django/template/base.py", line 835, in _resolve_lookup
    if isinstance(current, BaseContext) and getattr(type(current), bit):
AttributeError: type object 'RequestContext' has no attribute 'ascii_art'

During handling of the above exception, another exception occurred:

Traceback (most recent call last):
  File "/home/ubuntu/stringkeeper/lib/python3.8/site-packages/django/template/base.py", line 843, in _resolve_lookup
    current = current[int(bit)]
ValueError: invalid literal for int() with base 10: 'ascii_art'

During handling of the above exception, another exception occurred:

Traceback (most recent call last):
  File "/home/ubuntu/stringkeeper/lib/python3.8/site-packages/django/template/base.py", line 848, in _resolve_lookup
    raise VariableDoesNotExist("Failed lookup for key "
django.template.base.VariableDoesNotExist: Failed lookup for key [ascii_art] in [{'True': True, 'False': False, 'None': None}, {'csrf_token': <SimpleLazyObject: 'b2GHuG7Cj8hKJlKLSSuqSZZK0N5TnJecLvP12Vy6mZXILutaABN7e1nmGcfnDZ9q'>, 'request': <WSGIRequest: GET '/login/'>, 'user': <SimpleLazyObject: <django.contrib.auth.models.AnonymousUser object at 0x7f4912833d60>>, 'perms': <django.contrib.auth.context_processors.PermWrapper object at 0x7f4912bd5c70>, 'messages': <django.contrib.messages.storage.fallback.FallbackStorage object at 0x7f4912c17a60>, 'DEFAULT_MESSAGE_LEVELS': {'DEBUG': 10, 'INFO': 20, 'SUCCESS': 25, 'WARNING': 30, 'ERROR': 40}}, {}, {'form': <LoginForm bound=False, valid=False, fields=(email;password)>, 'view': <accounts.views.LoginView object at 0x7f4912be84c0>}]
Internal Server Error: /login/
Traceback (most recent call last):
  File "/home/ubuntu/stringkeeper/lib/python3.8/site-packages/django/core/handlers/exception.py", line 34, in inner
    response = get_response(request)
  File "/home/ubuntu/stringkeeper/lib/python3.8/site-packages/django/core/handlers/base.py", line 115, in _get_response
    response = self.process_exception_by_middleware(e, request)
  File "/home/ubuntu/stringkeeper/lib/python3.8/site-packages/django/core/handlers/base.py", line 113, in _get_response
    response = wrapped_callback(request, *callback_args, **callback_kwargs)
  File "/home/ubuntu/stringkeeper/lib/python3.8/site-packages/django/views/generic/base.py", line 71, in view
    return self.dispatch(request, *args, **kwargs)
  File "/home/ubuntu/stringkeeper/lib/python3.8/site-packages/django/views/generic/base.py", line 97, in dispatch
    return handler(request, *args, **kwargs)
  File "/home/ubuntu/stringkeeper/lib/python3.8/site-packages/django/views/generic/edit.py", line 142, in post
    return self.form_valid(form)
  File "/home/ubuntu/stringkeeper/accounts/views.py", line 130, in form_valid
    user_logged_in.send(user.__class__, instance=user, request=request)
  File "/home/ubuntu/stringkeeper/lib/python3.8/site-packages/django/dispatch/dispatcher.py", line 173, in send
    return [
  File "/home/ubuntu/stringkeeper/lib/python3.8/site-packages/django/dispatch/dispatcher.py", line 174, in <listcomp>
    (receiver, receiver(signal=self, sender=sender, **named))
  File "/home/ubuntu/stringkeeper/analytics/models.py", line 113, in user_logged_in_receiver
    UserSession.objects.create(
  File "/home/ubuntu/stringkeeper/lib/python3.8/site-packages/django/db/models/manager.py", line 82, in manager_method
    return getattr(self.get_queryset(), name)(*args, **kwargs)
  File "/home/ubuntu/stringkeeper/lib/python3.8/site-packages/django/db/models/query.py", line 422, in create
    obj.save(force_insert=True, using=self.db)
  File "/home/ubuntu/stringkeeper/lib/python3.8/site-packages/django/db/models/base.py", line 740, in save
    self.save_base(using=using, force_insert=force_insert,
  File "/home/ubuntu/stringkeeper/lib/python3.8/site-packages/django/db/models/base.py", line 788, in save_base
    post_save.send(
  File "/home/ubuntu/stringkeeper/lib/python3.8/site-packages/django/dispatch/dispatcher.py", line 173, in send
    return [
  File "/home/ubuntu/stringkeeper/lib/python3.8/site-packages/django/dispatch/dispatcher.py", line 174, in <listcomp>
    (receiver, receiver(signal=self, sender=sender, **named))
  File "/home/ubuntu/stringkeeper/analytics/models.py", line 85, in post_save_session_receiver
    qs = UserSession.objects.filter(user=instance.user, ended=False, is_active=True).exclude(id=instance.id)
  File "/home/ubuntu/stringkeeper/lib/python3.8/site-packages/django/db/models/manager.py", line 82, in manager_method
    return getattr(self.get_queryset(), name)(*args, **kwargs)
  File "/home/ubuntu/stringkeeper/lib/python3.8/site-packages/django/db/models/query.py", line 892, in filter
    return self._filter_or_exclude(False, *args, **kwargs)
  File "/home/ubuntu/stringkeeper/lib/python3.8/site-packages/django/db/models/query.py", line 910, in _filter_or_exclude
    clone.query.add_q(Q(*args, **kwargs))
  File "/home/ubuntu/stringkeeper/lib/python3.8/site-packages/django/db/models/sql/query.py", line 1290, in add_q
    clause, _ = self._add_q(q_object, self.used_aliases)
  File "/home/ubuntu/stringkeeper/lib/python3.8/site-packages/django/db/models/sql/query.py", line 1315, in _add_q
    child_clause, needed_inner = self.build_filter(
  File "/home/ubuntu/stringkeeper/lib/python3.8/site-packages/django/db/models/sql/query.py", line 1190, in build_filter
    lookups, parts, reffed_expression = self.solve_lookup_type(arg)
  File "/home/ubuntu/stringkeeper/lib/python3.8/site-packages/django/db/models/sql/query.py", line 1049, in solve_lookup_type
    _, field, _, lookup_parts = self.names_to_path(lookup_splitted, self.get_meta())
  File "/home/ubuntu/stringkeeper/lib/python3.8/site-packages/django/db/models/sql/query.py", line 1419, in names_to_path
    raise FieldError("Cannot resolve keyword '%s' into field. "
django.core.exceptions.FieldError: Cannot resolve keyword 'is_active' into field. Choices are: active, ended, id, ip_address, session_key, timestamp, user, user_id
