Exception while resolving variable 'cart_items' in template 'home.html'.
Traceback (most recent call last):
  File "/home/ubuntu/stringkeeper/lib/python3.8/site-packages/django/template/base.py", line 829, in _resolve_lookup
    current = current[bit]
  File "/home/ubuntu/stringkeeper/lib/python3.8/site-packages/django/contrib/sessions/backends/base.py", line 54, in __getitem__
    return self._session[key]
KeyError: 'cart_items'

During handling of the above exception, another exception occurred:

Traceback (most recent call last):
  File "/home/ubuntu/stringkeeper/lib/python3.8/site-packages/django/template/base.py", line 837, in _resolve_lookup
    current = getattr(current, bit)
AttributeError: 'SessionStore' object has no attribute 'cart_items'

During handling of the above exception, another exception occurred:

Traceback (most recent call last):
  File "/home/ubuntu/stringkeeper/lib/python3.8/site-packages/django/template/base.py", line 843, in _resolve_lookup
    current = current[int(bit)]
ValueError: invalid literal for int() with base 10: 'cart_items'

During handling of the above exception, another exception occurred:

Traceback (most recent call last):
  File "/home/ubuntu/stringkeeper/lib/python3.8/site-packages/django/template/base.py", line 848, in _resolve_lookup
    raise VariableDoesNotExist("Failed lookup for key "
django.template.base.VariableDoesNotExist: Failed lookup for key [cart_items] in <django.contrib.sessions.backends.db.SessionStore object at 0x7f9e4ae42af0>
Exception while resolving variable 'q' in template 'home.html'.
Traceback (most recent call last):
  File "/home/ubuntu/stringkeeper/lib/python3.8/site-packages/django/utils/datastructures.py", line 78, in __getitem__
    list_ = super().__getitem__(key)
KeyError: 'q'

During handling of the above exception, another exception occurred:

Traceback (most recent call last):
  File "/home/ubuntu/stringkeeper/lib/python3.8/site-packages/django/template/base.py", line 829, in _resolve_lookup
    current = current[bit]
  File "/home/ubuntu/stringkeeper/lib/python3.8/site-packages/django/utils/datastructures.py", line 80, in __getitem__
    raise MultiValueDictKeyError(key)
django.utils.datastructures.MultiValueDictKeyError: 'q'

During handling of the above exception, another exception occurred:

Traceback (most recent call last):
  File "/home/ubuntu/stringkeeper/lib/python3.8/site-packages/django/template/base.py", line 837, in _resolve_lookup
    current = getattr(current, bit)
AttributeError: 'QueryDict' object has no attribute 'q'

During handling of the above exception, another exception occurred:

Traceback (most recent call last):
  File "/home/ubuntu/stringkeeper/lib/python3.8/site-packages/django/template/base.py", line 843, in _resolve_lookup
    current = current[int(bit)]
ValueError: invalid literal for int() with base 10: 'q'

During handling of the above exception, another exception occurred:

Traceback (most recent call last):
  File "/home/ubuntu/stringkeeper/lib/python3.8/site-packages/django/template/base.py", line 848, in _resolve_lookup
    raise VariableDoesNotExist("Failed lookup for key "
django.template.base.VariableDoesNotExist: Failed lookup for key [q] in <QueryDict: {}>
Exception while resolving variable 'cart_items' in template 'home.html'.
Traceback (most recent call last):
  File "/home/ubuntu/stringkeeper/lib/python3.8/site-packages/django/template/base.py", line 829, in _resolve_lookup
    current = current[bit]
  File "/home/ubuntu/stringkeeper/lib/python3.8/site-packages/django/contrib/sessions/backends/base.py", line 54, in __getitem__
    return self._session[key]
KeyError: 'cart_items'

During handling of the above exception, another exception occurred:

Traceback (most recent call last):
  File "/home/ubuntu/stringkeeper/lib/python3.8/site-packages/django/template/base.py", line 837, in _resolve_lookup
    current = getattr(current, bit)
AttributeError: 'SessionStore' object has no attribute 'cart_items'

During handling of the above exception, another exception occurred:

Traceback (most recent call last):
  File "/home/ubuntu/stringkeeper/lib/python3.8/site-packages/django/template/base.py", line 843, in _resolve_lookup
    current = current[int(bit)]
ValueError: invalid literal for int() with base 10: 'cart_items'

During handling of the above exception, another exception occurred:

Traceback (most recent call last):
  File "/home/ubuntu/stringkeeper/lib/python3.8/site-packages/django/template/base.py", line 848, in _resolve_lookup
    raise VariableDoesNotExist("Failed lookup for key "
django.template.base.VariableDoesNotExist: Failed lookup for key [cart_items] in <django.contrib.sessions.backends.db.SessionStore object at 0x7f9e4aec09d0>
Exception while resolving variable 'q' in template 'home.html'.
Traceback (most recent call last):
  File "/home/ubuntu/stringkeeper/lib/python3.8/site-packages/django/utils/datastructures.py", line 78, in __getitem__
    list_ = super().__getitem__(key)
KeyError: 'q'

During handling of the above exception, another exception occurred:

Traceback (most recent call last):
  File "/home/ubuntu/stringkeeper/lib/python3.8/site-packages/django/template/base.py", line 829, in _resolve_lookup
    current = current[bit]
  File "/home/ubuntu/stringkeeper/lib/python3.8/site-packages/django/utils/datastructures.py", line 80, in __getitem__
    raise MultiValueDictKeyError(key)
django.utils.datastructures.MultiValueDictKeyError: 'q'

During handling of the above exception, another exception occurred:

Traceback (most recent call last):
  File "/home/ubuntu/stringkeeper/lib/python3.8/site-packages/django/template/base.py", line 837, in _resolve_lookup
    current = getattr(current, bit)
AttributeError: 'QueryDict' object has no attribute 'q'

During handling of the above exception, another exception occurred:

Traceback (most recent call last):
  File "/home/ubuntu/stringkeeper/lib/python3.8/site-packages/django/template/base.py", line 843, in _resolve_lookup
    current = current[int(bit)]
ValueError: invalid literal for int() with base 10: 'q'

During handling of the above exception, another exception occurred:

Traceback (most recent call last):
  File "/home/ubuntu/stringkeeper/lib/python3.8/site-packages/django/template/base.py", line 848, in _resolve_lookup
    raise VariableDoesNotExist("Failed lookup for key "
django.template.base.VariableDoesNotExist: Failed lookup for key [q] in <QueryDict: {}>
Exception while resolving variable 'cart_items' in template 'home.html'.
Traceback (most recent call last):
  File "/home/ubuntu/stringkeeper/lib/python3.8/site-packages/django/template/base.py", line 829, in _resolve_lookup
    current = current[bit]
  File "/home/ubuntu/stringkeeper/lib/python3.8/site-packages/django/contrib/sessions/backends/base.py", line 54, in __getitem__
    return self._session[key]
KeyError: 'cart_items'

During handling of the above exception, another exception occurred:

Traceback (most recent call last):
  File "/home/ubuntu/stringkeeper/lib/python3.8/site-packages/django/template/base.py", line 837, in _resolve_lookup
    current = getattr(current, bit)
AttributeError: 'SessionStore' object has no attribute 'cart_items'

During handling of the above exception, another exception occurred:

Traceback (most recent call last):
  File "/home/ubuntu/stringkeeper/lib/python3.8/site-packages/django/template/base.py", line 843, in _resolve_lookup
    current = current[int(bit)]
ValueError: invalid literal for int() with base 10: 'cart_items'

During handling of the above exception, another exception occurred:

Traceback (most recent call last):
  File "/home/ubuntu/stringkeeper/lib/python3.8/site-packages/django/template/base.py", line 848, in _resolve_lookup
    raise VariableDoesNotExist("Failed lookup for key "
django.template.base.VariableDoesNotExist: Failed lookup for key [cart_items] in <django.contrib.sessions.backends.db.SessionStore object at 0x7f9e4a17a2b0>
Exception while resolving variable 'q' in template 'home.html'.
Traceback (most recent call last):
  File "/home/ubuntu/stringkeeper/lib/python3.8/site-packages/django/utils/datastructures.py", line 78, in __getitem__
    list_ = super().__getitem__(key)
KeyError: 'q'

During handling of the above exception, another exception occurred:

Traceback (most recent call last):
  File "/home/ubuntu/stringkeeper/lib/python3.8/site-packages/django/template/base.py", line 829, in _resolve_lookup
    current = current[bit]
  File "/home/ubuntu/stringkeeper/lib/python3.8/site-packages/django/utils/datastructures.py", line 80, in __getitem__
    raise MultiValueDictKeyError(key)
django.utils.datastructures.MultiValueDictKeyError: 'q'

During handling of the above exception, another exception occurred:

Traceback (most recent call last):
  File "/home/ubuntu/stringkeeper/lib/python3.8/site-packages/django/template/base.py", line 837, in _resolve_lookup
    current = getattr(current, bit)
AttributeError: 'QueryDict' object has no attribute 'q'

During handling of the above exception, another exception occurred:

Traceback (most recent call last):
  File "/home/ubuntu/stringkeeper/lib/python3.8/site-packages/django/template/base.py", line 843, in _resolve_lookup
    current = current[int(bit)]
ValueError: invalid literal for int() with base 10: 'q'

During handling of the above exception, another exception occurred:

Traceback (most recent call last):
  File "/home/ubuntu/stringkeeper/lib/python3.8/site-packages/django/template/base.py", line 848, in _resolve_lookup
    raise VariableDoesNotExist("Failed lookup for key "
django.template.base.VariableDoesNotExist: Failed lookup for key [q] in <QueryDict: {}>
Exception while resolving variable 'cart_items' in template 'accounts/login.html'.
Traceback (most recent call last):
  File "/home/ubuntu/stringkeeper/lib/python3.8/site-packages/django/template/base.py", line 829, in _resolve_lookup
    current = current[bit]
  File "/home/ubuntu/stringkeeper/lib/python3.8/site-packages/django/contrib/sessions/backends/base.py", line 54, in __getitem__
    return self._session[key]
KeyError: 'cart_items'

During handling of the above exception, another exception occurred:

Traceback (most recent call last):
  File "/home/ubuntu/stringkeeper/lib/python3.8/site-packages/django/template/base.py", line 837, in _resolve_lookup
    current = getattr(current, bit)
AttributeError: 'SessionStore' object has no attribute 'cart_items'

During handling of the above exception, another exception occurred:

Traceback (most recent call last):
  File "/home/ubuntu/stringkeeper/lib/python3.8/site-packages/django/template/base.py", line 843, in _resolve_lookup
    current = current[int(bit)]
ValueError: invalid literal for int() with base 10: 'cart_items'

During handling of the above exception, another exception occurred:

Traceback (most recent call last):
  File "/home/ubuntu/stringkeeper/lib/python3.8/site-packages/django/template/base.py", line 848, in _resolve_lookup
    raise VariableDoesNotExist("Failed lookup for key "
django.template.base.VariableDoesNotExist: Failed lookup for key [cart_items] in <django.contrib.sessions.backends.db.SessionStore object at 0x7f9e490f1e80>
Exception while resolving variable 'q' in template 'accounts/login.html'.
Traceback (most recent call last):
  File "/home/ubuntu/stringkeeper/lib/python3.8/site-packages/django/utils/datastructures.py", line 78, in __getitem__
    list_ = super().__getitem__(key)
KeyError: 'q'

During handling of the above exception, another exception occurred:

Traceback (most recent call last):
  File "/home/ubuntu/stringkeeper/lib/python3.8/site-packages/django/template/base.py", line 829, in _resolve_lookup
    current = current[bit]
  File "/home/ubuntu/stringkeeper/lib/python3.8/site-packages/django/utils/datastructures.py", line 80, in __getitem__
    raise MultiValueDictKeyError(key)
django.utils.datastructures.MultiValueDictKeyError: 'q'

During handling of the above exception, another exception occurred:

Traceback (most recent call last):
  File "/home/ubuntu/stringkeeper/lib/python3.8/site-packages/django/template/base.py", line 837, in _resolve_lookup
    current = getattr(current, bit)
AttributeError: 'QueryDict' object has no attribute 'q'

During handling of the above exception, another exception occurred:

Traceback (most recent call last):
  File "/home/ubuntu/stringkeeper/lib/python3.8/site-packages/django/template/base.py", line 843, in _resolve_lookup
    current = current[int(bit)]
ValueError: invalid literal for int() with base 10: 'q'

During handling of the above exception, another exception occurred:

Traceback (most recent call last):
  File "/home/ubuntu/stringkeeper/lib/python3.8/site-packages/django/template/base.py", line 848, in _resolve_lookup
    raise VariableDoesNotExist("Failed lookup for key "
django.template.base.VariableDoesNotExist: Failed lookup for key [q] in <QueryDict: {}>
Exception while resolving variable 'ascii_art' in template 'accounts/login.html'.
Traceback (most recent call last):
  File "/home/ubuntu/stringkeeper/lib/python3.8/site-packages/django/template/base.py", line 829, in _resolve_lookup
    current = current[bit]
  File "/home/ubuntu/stringkeeper/lib/python3.8/site-packages/django/template/context.py", line 83, in __getitem__
    raise KeyError(key)
KeyError: 'ascii_art'

During handling of the above exception, another exception occurred:

Traceback (most recent call last):
  File "/home/ubuntu/stringkeeper/lib/python3.8/site-packages/django/template/base.py", line 835, in _resolve_lookup
    if isinstance(current, BaseContext) and getattr(type(current), bit):
AttributeError: type object 'RequestContext' has no attribute 'ascii_art'

During handling of the above exception, another exception occurred:

Traceback (most recent call last):
  File "/home/ubuntu/stringkeeper/lib/python3.8/site-packages/django/template/base.py", line 843, in _resolve_lookup
    current = current[int(bit)]
ValueError: invalid literal for int() with base 10: 'ascii_art'

During handling of the above exception, another exception occurred:

Traceback (most recent call last):
  File "/home/ubuntu/stringkeeper/lib/python3.8/site-packages/django/template/base.py", line 848, in _resolve_lookup
    raise VariableDoesNotExist("Failed lookup for key "
django.template.base.VariableDoesNotExist: Failed lookup for key [ascii_art] in [{'True': True, 'False': False, 'None': None}, {'csrf_token': <SimpleLazyObject: '9GeVFauDqXEDIAGjyFhwZA8tgqIdP5G5750tThIVUKJlayv1EQQem190i7TlmP0H'>, 'request': <WSGIRequest: GET '/login/'>, 'user': <SimpleLazyObject: <django.contrib.auth.models.AnonymousUser object at 0x7f9e491c28b0>>, 'perms': <django.contrib.auth.context_processors.PermWrapper object at 0x7f9e4910c370>, 'messages': <django.contrib.messages.storage.fallback.FallbackStorage object at 0x7f9e490f1850>, 'DEFAULT_MESSAGE_LEVELS': {'DEBUG': 10, 'INFO': 20, 'SUCCESS': 25, 'WARNING': 30, 'ERROR': 40}}, {}, {'form': <LoginForm bound=False, valid=False, fields=(email;password)>, 'view': <accounts.views.LoginView object at 0x7f9e490f19d0>}]
Exception while resolving variable 'cart_items' in template 'home.html'.
Traceback (most recent call last):
  File "/home/ubuntu/stringkeeper/lib/python3.8/site-packages/django/template/base.py", line 829, in _resolve_lookup
    current = current[bit]
  File "/home/ubuntu/stringkeeper/lib/python3.8/site-packages/django/contrib/sessions/backends/base.py", line 54, in __getitem__
    return self._session[key]
KeyError: 'cart_items'

During handling of the above exception, another exception occurred:

Traceback (most recent call last):
  File "/home/ubuntu/stringkeeper/lib/python3.8/site-packages/django/template/base.py", line 837, in _resolve_lookup
    current = getattr(current, bit)
AttributeError: 'SessionStore' object has no attribute 'cart_items'

During handling of the above exception, another exception occurred:

Traceback (most recent call last):
  File "/home/ubuntu/stringkeeper/lib/python3.8/site-packages/django/template/base.py", line 843, in _resolve_lookup
    current = current[int(bit)]
ValueError: invalid literal for int() with base 10: 'cart_items'

During handling of the above exception, another exception occurred:

Traceback (most recent call last):
  File "/home/ubuntu/stringkeeper/lib/python3.8/site-packages/django/template/base.py", line 848, in _resolve_lookup
    raise VariableDoesNotExist("Failed lookup for key "
django.template.base.VariableDoesNotExist: Failed lookup for key [cart_items] in <django.contrib.sessions.backends.db.SessionStore object at 0x7f9e4919a0a0>
Exception while resolving variable 'q' in template 'home.html'.
Traceback (most recent call last):
  File "/home/ubuntu/stringkeeper/lib/python3.8/site-packages/django/utils/datastructures.py", line 78, in __getitem__
    list_ = super().__getitem__(key)
KeyError: 'q'

During handling of the above exception, another exception occurred:

Traceback (most recent call last):
  File "/home/ubuntu/stringkeeper/lib/python3.8/site-packages/django/template/base.py", line 829, in _resolve_lookup
    current = current[bit]
  File "/home/ubuntu/stringkeeper/lib/python3.8/site-packages/django/utils/datastructures.py", line 80, in __getitem__
    raise MultiValueDictKeyError(key)
django.utils.datastructures.MultiValueDictKeyError: 'q'

During handling of the above exception, another exception occurred:

Traceback (most recent call last):
  File "/home/ubuntu/stringkeeper/lib/python3.8/site-packages/django/template/base.py", line 837, in _resolve_lookup
    current = getattr(current, bit)
AttributeError: 'QueryDict' object has no attribute 'q'

During handling of the above exception, another exception occurred:

Traceback (most recent call last):
  File "/home/ubuntu/stringkeeper/lib/python3.8/site-packages/django/template/base.py", line 843, in _resolve_lookup
    current = current[int(bit)]
ValueError: invalid literal for int() with base 10: 'q'

During handling of the above exception, another exception occurred:

Traceback (most recent call last):
  File "/home/ubuntu/stringkeeper/lib/python3.8/site-packages/django/template/base.py", line 848, in _resolve_lookup
    raise VariableDoesNotExist("Failed lookup for key "
django.template.base.VariableDoesNotExist: Failed lookup for key [q] in <QueryDict: {}>
Exception while resolving variable 'cart_items' in template 'accounts/register.html'.
Traceback (most recent call last):
  File "/home/ubuntu/stringkeeper/lib/python3.8/site-packages/django/template/base.py", line 829, in _resolve_lookup
    current = current[bit]
  File "/home/ubuntu/stringkeeper/lib/python3.8/site-packages/django/contrib/sessions/backends/base.py", line 54, in __getitem__
    return self._session[key]
KeyError: 'cart_items'

During handling of the above exception, another exception occurred:

Traceback (most recent call last):
  File "/home/ubuntu/stringkeeper/lib/python3.8/site-packages/django/template/base.py", line 837, in _resolve_lookup
    current = getattr(current, bit)
AttributeError: 'SessionStore' object has no attribute 'cart_items'

During handling of the above exception, another exception occurred:

Traceback (most recent call last):
  File "/home/ubuntu/stringkeeper/lib/python3.8/site-packages/django/template/base.py", line 843, in _resolve_lookup
    current = current[int(bit)]
ValueError: invalid literal for int() with base 10: 'cart_items'

During handling of the above exception, another exception occurred:

Traceback (most recent call last):
  File "/home/ubuntu/stringkeeper/lib/python3.8/site-packages/django/template/base.py", line 848, in _resolve_lookup
    raise VariableDoesNotExist("Failed lookup for key "
django.template.base.VariableDoesNotExist: Failed lookup for key [cart_items] in <django.contrib.sessions.backends.db.SessionStore object at 0x7f9e490bb0a0>
Exception while resolving variable 'q' in template 'accounts/register.html'.
Traceback (most recent call last):
  File "/home/ubuntu/stringkeeper/lib/python3.8/site-packages/django/utils/datastructures.py", line 78, in __getitem__
    list_ = super().__getitem__(key)
KeyError: 'q'

During handling of the above exception, another exception occurred:

Traceback (most recent call last):
  File "/home/ubuntu/stringkeeper/lib/python3.8/site-packages/django/template/base.py", line 829, in _resolve_lookup
    current = current[bit]
  File "/home/ubuntu/stringkeeper/lib/python3.8/site-packages/django/utils/datastructures.py", line 80, in __getitem__
    raise MultiValueDictKeyError(key)
django.utils.datastructures.MultiValueDictKeyError: 'q'

During handling of the above exception, another exception occurred:

Traceback (most recent call last):
  File "/home/ubuntu/stringkeeper/lib/python3.8/site-packages/django/template/base.py", line 837, in _resolve_lookup
    current = getattr(current, bit)
AttributeError: 'QueryDict' object has no attribute 'q'

During handling of the above exception, another exception occurred:

Traceback (most recent call last):
  File "/home/ubuntu/stringkeeper/lib/python3.8/site-packages/django/template/base.py", line 843, in _resolve_lookup
    current = current[int(bit)]
ValueError: invalid literal for int() with base 10: 'q'

During handling of the above exception, another exception occurred:

Traceback (most recent call last):
  File "/home/ubuntu/stringkeeper/lib/python3.8/site-packages/django/template/base.py", line 848, in _resolve_lookup
    raise VariableDoesNotExist("Failed lookup for key "
django.template.base.VariableDoesNotExist: Failed lookup for key [q] in <QueryDict: {}>
Exception while resolving variable 'ascii_art' in template 'accounts/register.html'.
Traceback (most recent call last):
  File "/home/ubuntu/stringkeeper/lib/python3.8/site-packages/django/template/base.py", line 829, in _resolve_lookup
    current = current[bit]
  File "/home/ubuntu/stringkeeper/lib/python3.8/site-packages/django/template/context.py", line 83, in __getitem__
    raise KeyError(key)
KeyError: 'ascii_art'

During handling of the above exception, another exception occurred:

Traceback (most recent call last):
  File "/home/ubuntu/stringkeeper/lib/python3.8/site-packages/django/template/base.py", line 835, in _resolve_lookup
    if isinstance(current, BaseContext) and getattr(type(current), bit):
AttributeError: type object 'RequestContext' has no attribute 'ascii_art'

During handling of the above exception, another exception occurred:

Traceback (most recent call last):
  File "/home/ubuntu/stringkeeper/lib/python3.8/site-packages/django/template/base.py", line 843, in _resolve_lookup
    current = current[int(bit)]
ValueError: invalid literal for int() with base 10: 'ascii_art'

During handling of the above exception, another exception occurred:

Traceback (most recent call last):
  File "/home/ubuntu/stringkeeper/lib/python3.8/site-packages/django/template/base.py", line 848, in _resolve_lookup
    raise VariableDoesNotExist("Failed lookup for key "
django.template.base.VariableDoesNotExist: Failed lookup for key [ascii_art] in [{'True': True, 'False': False, 'None': None}, {'csrf_token': <SimpleLazyObject: '0TjmfPI4Udbro64wJBbD0XwKk50YNc4pXLESf74JTu0c8u6gwD0MpRr8JbsPRxMg'>, 'request': <WSGIRequest: GET '/register/'>, 'user': <SimpleLazyObject: <django.contrib.auth.models.AnonymousUser object at 0x7f9e48fe8b80>>, 'perms': <django.contrib.auth.context_processors.PermWrapper object at 0x7f9e48fe80a0>, 'messages': <django.contrib.messages.storage.fallback.FallbackStorage object at 0x7f9e490bb1f0>, 'DEFAULT_MESSAGE_LEVELS': {'DEBUG': 10, 'INFO': 20, 'SUCCESS': 25, 'WARNING': 30, 'ERROR': 40}}, {}, {'form': <RegisterForm bound=False, valid=False, fields=(first_name;last_name;email;password1;password2)>, 'view': <accounts.views.RegisterView object at 0x7f9e490bb1c0>}]
Exception while resolving variable 'cart_items' in template 'accounts/login.html'.
Traceback (most recent call last):
  File "/home/ubuntu/stringkeeper/lib/python3.8/site-packages/django/template/base.py", line 829, in _resolve_lookup
    current = current[bit]
  File "/home/ubuntu/stringkeeper/lib/python3.8/site-packages/django/contrib/sessions/backends/base.py", line 54, in __getitem__
    return self._session[key]
KeyError: 'cart_items'

During handling of the above exception, another exception occurred:

Traceback (most recent call last):
  File "/home/ubuntu/stringkeeper/lib/python3.8/site-packages/django/template/base.py", line 837, in _resolve_lookup
    current = getattr(current, bit)
AttributeError: 'SessionStore' object has no attribute 'cart_items'

During handling of the above exception, another exception occurred:

Traceback (most recent call last):
  File "/home/ubuntu/stringkeeper/lib/python3.8/site-packages/django/template/base.py", line 843, in _resolve_lookup
    current = current[int(bit)]
ValueError: invalid literal for int() with base 10: 'cart_items'

During handling of the above exception, another exception occurred:

Traceback (most recent call last):
  File "/home/ubuntu/stringkeeper/lib/python3.8/site-packages/django/template/base.py", line 848, in _resolve_lookup
    raise VariableDoesNotExist("Failed lookup for key "
django.template.base.VariableDoesNotExist: Failed lookup for key [cart_items] in <django.contrib.sessions.backends.db.SessionStore object at 0x7f9e49059e80>
Exception while resolving variable 'q' in template 'accounts/login.html'.
Traceback (most recent call last):
  File "/home/ubuntu/stringkeeper/lib/python3.8/site-packages/django/utils/datastructures.py", line 78, in __getitem__
    list_ = super().__getitem__(key)
KeyError: 'q'

During handling of the above exception, another exception occurred:

Traceback (most recent call last):
  File "/home/ubuntu/stringkeeper/lib/python3.8/site-packages/django/template/base.py", line 829, in _resolve_lookup
    current = current[bit]
  File "/home/ubuntu/stringkeeper/lib/python3.8/site-packages/django/utils/datastructures.py", line 80, in __getitem__
    raise MultiValueDictKeyError(key)
django.utils.datastructures.MultiValueDictKeyError: 'q'

During handling of the above exception, another exception occurred:

Traceback (most recent call last):
  File "/home/ubuntu/stringkeeper/lib/python3.8/site-packages/django/template/base.py", line 837, in _resolve_lookup
    current = getattr(current, bit)
AttributeError: 'QueryDict' object has no attribute 'q'

During handling of the above exception, another exception occurred:

Traceback (most recent call last):
  File "/home/ubuntu/stringkeeper/lib/python3.8/site-packages/django/template/base.py", line 843, in _resolve_lookup
    current = current[int(bit)]
ValueError: invalid literal for int() with base 10: 'q'

During handling of the above exception, another exception occurred:

Traceback (most recent call last):
  File "/home/ubuntu/stringkeeper/lib/python3.8/site-packages/django/template/base.py", line 848, in _resolve_lookup
    raise VariableDoesNotExist("Failed lookup for key "
django.template.base.VariableDoesNotExist: Failed lookup for key [q] in <QueryDict: {}>
Exception while resolving variable 'ascii_art' in template 'accounts/login.html'.
Traceback (most recent call last):
  File "/home/ubuntu/stringkeeper/lib/python3.8/site-packages/django/template/base.py", line 829, in _resolve_lookup
    current = current[bit]
  File "/home/ubuntu/stringkeeper/lib/python3.8/site-packages/django/template/context.py", line 83, in __getitem__
    raise KeyError(key)
KeyError: 'ascii_art'

During handling of the above exception, another exception occurred:

Traceback (most recent call last):
  File "/home/ubuntu/stringkeeper/lib/python3.8/site-packages/django/template/base.py", line 835, in _resolve_lookup
    if isinstance(current, BaseContext) and getattr(type(current), bit):
AttributeError: type object 'RequestContext' has no attribute 'ascii_art'

During handling of the above exception, another exception occurred:

Traceback (most recent call last):
  File "/home/ubuntu/stringkeeper/lib/python3.8/site-packages/django/template/base.py", line 843, in _resolve_lookup
    current = current[int(bit)]
ValueError: invalid literal for int() with base 10: 'ascii_art'

During handling of the above exception, another exception occurred:

Traceback (most recent call last):
  File "/home/ubuntu/stringkeeper/lib/python3.8/site-packages/django/template/base.py", line 848, in _resolve_lookup
    raise VariableDoesNotExist("Failed lookup for key "
django.template.base.VariableDoesNotExist: Failed lookup for key [ascii_art] in [{'True': True, 'False': False, 'None': None}, {'csrf_token': <SimpleLazyObject: 'FUlPuUk9khEOLIM3gKsUSkzcuHmzXKbnCMGlucGOjytzv6ON3Mh3heuATNOq15Te'>, 'request': <WSGIRequest: GET '/login/'>, 'user': <SimpleLazyObject: <django.contrib.auth.models.AnonymousUser object at 0x7f9e48ffb430>>, 'perms': <django.contrib.auth.context_processors.PermWrapper object at 0x7f9e48fef970>, 'messages': <django.contrib.messages.storage.fallback.FallbackStorage object at 0x7f9e48fe8040>, 'DEFAULT_MESSAGE_LEVELS': {'DEBUG': 10, 'INFO': 20, 'SUCCESS': 25, 'WARNING': 30, 'ERROR': 40}}, {}, {'form': <LoginForm bound=False, valid=False, fields=(email;password)>, 'view': <accounts.views.LoginView object at 0x7f9e48fe8070>}]
Exception while resolving variable 'cart_items' in template 'home.html'.
Traceback (most recent call last):
  File "/home/ubuntu/stringkeeper/lib/python3.8/site-packages/django/template/base.py", line 829, in _resolve_lookup
    current = current[bit]
  File "/home/ubuntu/stringkeeper/lib/python3.8/site-packages/django/contrib/sessions/backends/base.py", line 54, in __getitem__
    return self._session[key]
KeyError: 'cart_items'

During handling of the above exception, another exception occurred:

Traceback (most recent call last):
  File "/home/ubuntu/stringkeeper/lib/python3.8/site-packages/django/template/base.py", line 837, in _resolve_lookup
    current = getattr(current, bit)
AttributeError: 'SessionStore' object has no attribute 'cart_items'

During handling of the above exception, another exception occurred:

Traceback (most recent call last):
  File "/home/ubuntu/stringkeeper/lib/python3.8/site-packages/django/template/base.py", line 843, in _resolve_lookup
    current = current[int(bit)]
ValueError: invalid literal for int() with base 10: 'cart_items'

During handling of the above exception, another exception occurred:

Traceback (most recent call last):
  File "/home/ubuntu/stringkeeper/lib/python3.8/site-packages/django/template/base.py", line 848, in _resolve_lookup
    raise VariableDoesNotExist("Failed lookup for key "
django.template.base.VariableDoesNotExist: Failed lookup for key [cart_items] in <django.contrib.sessions.backends.db.SessionStore object at 0x7f9e48fef940>
Exception while resolving variable 'q' in template 'home.html'.
Traceback (most recent call last):
  File "/home/ubuntu/stringkeeper/lib/python3.8/site-packages/django/utils/datastructures.py", line 78, in __getitem__
    list_ = super().__getitem__(key)
KeyError: 'q'

During handling of the above exception, another exception occurred:

Traceback (most recent call last):
  File "/home/ubuntu/stringkeeper/lib/python3.8/site-packages/django/template/base.py", line 829, in _resolve_lookup
    current = current[bit]
  File "/home/ubuntu/stringkeeper/lib/python3.8/site-packages/django/utils/datastructures.py", line 80, in __getitem__
    raise MultiValueDictKeyError(key)
django.utils.datastructures.MultiValueDictKeyError: 'q'

During handling of the above exception, another exception occurred:

Traceback (most recent call last):
  File "/home/ubuntu/stringkeeper/lib/python3.8/site-packages/django/template/base.py", line 837, in _resolve_lookup
    current = getattr(current, bit)
AttributeError: 'QueryDict' object has no attribute 'q'

During handling of the above exception, another exception occurred:

Traceback (most recent call last):
  File "/home/ubuntu/stringkeeper/lib/python3.8/site-packages/django/template/base.py", line 843, in _resolve_lookup
    current = current[int(bit)]
ValueError: invalid literal for int() with base 10: 'q'

During handling of the above exception, another exception occurred:

Traceback (most recent call last):
  File "/home/ubuntu/stringkeeper/lib/python3.8/site-packages/django/template/base.py", line 848, in _resolve_lookup
    raise VariableDoesNotExist("Failed lookup for key "
django.template.base.VariableDoesNotExist: Failed lookup for key [q] in <QueryDict: {}>
Exception while resolving variable 'cart_items' in template 'accounts/login.html'.
Traceback (most recent call last):
  File "/home/ubuntu/stringkeeper/lib/python3.8/site-packages/django/template/base.py", line 829, in _resolve_lookup
    current = current[bit]
  File "/home/ubuntu/stringkeeper/lib/python3.8/site-packages/django/contrib/sessions/backends/base.py", line 54, in __getitem__
    return self._session[key]
KeyError: 'cart_items'

During handling of the above exception, another exception occurred:

Traceback (most recent call last):
  File "/home/ubuntu/stringkeeper/lib/python3.8/site-packages/django/template/base.py", line 837, in _resolve_lookup
    current = getattr(current, bit)
AttributeError: 'SessionStore' object has no attribute 'cart_items'

During handling of the above exception, another exception occurred:

Traceback (most recent call last):
  File "/home/ubuntu/stringkeeper/lib/python3.8/site-packages/django/template/base.py", line 843, in _resolve_lookup
    current = current[int(bit)]
ValueError: invalid literal for int() with base 10: 'cart_items'

During handling of the above exception, another exception occurred:

Traceback (most recent call last):
  File "/home/ubuntu/stringkeeper/lib/python3.8/site-packages/django/template/base.py", line 848, in _resolve_lookup
    raise VariableDoesNotExist("Failed lookup for key "
django.template.base.VariableDoesNotExist: Failed lookup for key [cart_items] in <django.contrib.sessions.backends.db.SessionStore object at 0x7f9e49062280>
Exception while resolving variable 'q' in template 'accounts/login.html'.
Traceback (most recent call last):
  File "/home/ubuntu/stringkeeper/lib/python3.8/site-packages/django/utils/datastructures.py", line 78, in __getitem__
    list_ = super().__getitem__(key)
KeyError: 'q'

During handling of the above exception, another exception occurred:

Traceback (most recent call last):
  File "/home/ubuntu/stringkeeper/lib/python3.8/site-packages/django/template/base.py", line 829, in _resolve_lookup
    current = current[bit]
  File "/home/ubuntu/stringkeeper/lib/python3.8/site-packages/django/utils/datastructures.py", line 80, in __getitem__
    raise MultiValueDictKeyError(key)
django.utils.datastructures.MultiValueDictKeyError: 'q'

During handling of the above exception, another exception occurred:

Traceback (most recent call last):
  File "/home/ubuntu/stringkeeper/lib/python3.8/site-packages/django/template/base.py", line 837, in _resolve_lookup
    current = getattr(current, bit)
AttributeError: 'QueryDict' object has no attribute 'q'

During handling of the above exception, another exception occurred:

Traceback (most recent call last):
  File "/home/ubuntu/stringkeeper/lib/python3.8/site-packages/django/template/base.py", line 843, in _resolve_lookup
    current = current[int(bit)]
ValueError: invalid literal for int() with base 10: 'q'

During handling of the above exception, another exception occurred:

Traceback (most recent call last):
  File "/home/ubuntu/stringkeeper/lib/python3.8/site-packages/django/template/base.py", line 848, in _resolve_lookup
    raise VariableDoesNotExist("Failed lookup for key "
django.template.base.VariableDoesNotExist: Failed lookup for key [q] in <QueryDict: {}>
Exception while resolving variable 'ascii_art' in template 'accounts/login.html'.
Traceback (most recent call last):
  File "/home/ubuntu/stringkeeper/lib/python3.8/site-packages/django/template/base.py", line 829, in _resolve_lookup
    current = current[bit]
  File "/home/ubuntu/stringkeeper/lib/python3.8/site-packages/django/template/context.py", line 83, in __getitem__
    raise KeyError(key)
KeyError: 'ascii_art'

During handling of the above exception, another exception occurred:

Traceback (most recent call last):
  File "/home/ubuntu/stringkeeper/lib/python3.8/site-packages/django/template/base.py", line 835, in _resolve_lookup
    if isinstance(current, BaseContext) and getattr(type(current), bit):
AttributeError: type object 'RequestContext' has no attribute 'ascii_art'

During handling of the above exception, another exception occurred:

Traceback (most recent call last):
  File "/home/ubuntu/stringkeeper/lib/python3.8/site-packages/django/template/base.py", line 843, in _resolve_lookup
    current = current[int(bit)]
ValueError: invalid literal for int() with base 10: 'ascii_art'

During handling of the above exception, another exception occurred:

Traceback (most recent call last):
  File "/home/ubuntu/stringkeeper/lib/python3.8/site-packages/django/template/base.py", line 848, in _resolve_lookup
    raise VariableDoesNotExist("Failed lookup for key "
django.template.base.VariableDoesNotExist: Failed lookup for key [ascii_art] in [{'True': True, 'False': False, 'None': None}, {'csrf_token': <SimpleLazyObject: 'ev3DEpey2OC2sPGZSKgitYqUjMJNnESVRcma9g0GkW8ZwKOU4Y2GSZTOogzIZHyy'>, 'request': <WSGIRequest: GET '/login/'>, 'user': <SimpleLazyObject: <django.contrib.auth.models.AnonymousUser object at 0x7f9e49062d00>>, 'perms': <django.contrib.auth.context_processors.PermWrapper object at 0x7f9e49062a00>, 'messages': <django.contrib.messages.storage.fallback.FallbackStorage object at 0x7f9e490620d0>, 'DEFAULT_MESSAGE_LEVELS': {'DEBUG': 10, 'INFO': 20, 'SUCCESS': 25, 'WARNING': 30, 'ERROR': 40}}, {}, {'form': <LoginForm bound=False, valid=False, fields=(email;password)>, 'view': <accounts.views.LoginView object at 0x7f9e49062160>}]
Exception while resolving variable 'cart_items' in template 'accounts/register.html'.
Traceback (most recent call last):
  File "/home/ubuntu/stringkeeper/lib/python3.8/site-packages/django/template/base.py", line 829, in _resolve_lookup
    current = current[bit]
  File "/home/ubuntu/stringkeeper/lib/python3.8/site-packages/django/contrib/sessions/backends/base.py", line 54, in __getitem__
    return self._session[key]
KeyError: 'cart_items'

During handling of the above exception, another exception occurred:

Traceback (most recent call last):
  File "/home/ubuntu/stringkeeper/lib/python3.8/site-packages/django/template/base.py", line 837, in _resolve_lookup
    current = getattr(current, bit)
AttributeError: 'SessionStore' object has no attribute 'cart_items'

During handling of the above exception, another exception occurred:

Traceback (most recent call last):
  File "/home/ubuntu/stringkeeper/lib/python3.8/site-packages/django/template/base.py", line 843, in _resolve_lookup
    current = current[int(bit)]
ValueError: invalid literal for int() with base 10: 'cart_items'

During handling of the above exception, another exception occurred:

Traceback (most recent call last):
  File "/home/ubuntu/stringkeeper/lib/python3.8/site-packages/django/template/base.py", line 848, in _resolve_lookup
    raise VariableDoesNotExist("Failed lookup for key "
django.template.base.VariableDoesNotExist: Failed lookup for key [cart_items] in <django.contrib.sessions.backends.db.SessionStore object at 0x7f9e48fce9a0>
Exception while resolving variable 'q' in template 'accounts/register.html'.
Traceback (most recent call last):
  File "/home/ubuntu/stringkeeper/lib/python3.8/site-packages/django/utils/datastructures.py", line 78, in __getitem__
    list_ = super().__getitem__(key)
KeyError: 'q'

During handling of the above exception, another exception occurred:

Traceback (most recent call last):
  File "/home/ubuntu/stringkeeper/lib/python3.8/site-packages/django/template/base.py", line 829, in _resolve_lookup
    current = current[bit]
  File "/home/ubuntu/stringkeeper/lib/python3.8/site-packages/django/utils/datastructures.py", line 80, in __getitem__
    raise MultiValueDictKeyError(key)
django.utils.datastructures.MultiValueDictKeyError: 'q'

During handling of the above exception, another exception occurred:

Traceback (most recent call last):
  File "/home/ubuntu/stringkeeper/lib/python3.8/site-packages/django/template/base.py", line 837, in _resolve_lookup
    current = getattr(current, bit)
AttributeError: 'QueryDict' object has no attribute 'q'

During handling of the above exception, another exception occurred:

Traceback (most recent call last):
  File "/home/ubuntu/stringkeeper/lib/python3.8/site-packages/django/template/base.py", line 843, in _resolve_lookup
    current = current[int(bit)]
ValueError: invalid literal for int() with base 10: 'q'

During handling of the above exception, another exception occurred:

Traceback (most recent call last):
  File "/home/ubuntu/stringkeeper/lib/python3.8/site-packages/django/template/base.py", line 848, in _resolve_lookup
    raise VariableDoesNotExist("Failed lookup for key "
django.template.base.VariableDoesNotExist: Failed lookup for key [q] in <QueryDict: {}>
Exception while resolving variable 'ascii_art' in template 'accounts/register.html'.
Traceback (most recent call last):
  File "/home/ubuntu/stringkeeper/lib/python3.8/site-packages/django/template/base.py", line 829, in _resolve_lookup
    current = current[bit]
  File "/home/ubuntu/stringkeeper/lib/python3.8/site-packages/django/template/context.py", line 83, in __getitem__
    raise KeyError(key)
KeyError: 'ascii_art'

During handling of the above exception, another exception occurred:

Traceback (most recent call last):
  File "/home/ubuntu/stringkeeper/lib/python3.8/site-packages/django/template/base.py", line 835, in _resolve_lookup
    if isinstance(current, BaseContext) and getattr(type(current), bit):
AttributeError: type object 'RequestContext' has no attribute 'ascii_art'

During handling of the above exception, another exception occurred:

Traceback (most recent call last):
  File "/home/ubuntu/stringkeeper/lib/python3.8/site-packages/django/template/base.py", line 843, in _resolve_lookup
    current = current[int(bit)]
ValueError: invalid literal for int() with base 10: 'ascii_art'

During handling of the above exception, another exception occurred:

Traceback (most recent call last):
  File "/home/ubuntu/stringkeeper/lib/python3.8/site-packages/django/template/base.py", line 848, in _resolve_lookup
    raise VariableDoesNotExist("Failed lookup for key "
django.template.base.VariableDoesNotExist: Failed lookup for key [ascii_art] in [{'True': True, 'False': False, 'None': None}, {'csrf_token': <SimpleLazyObject: 'wT6eFQd5TtOiTZEZWzyVvJhikvq9Dj1ruiSMTXrnngT0lXtH2K7DSaiPmcBha3l3'>, 'request': <WSGIRequest: GET '/register/'>, 'user': <SimpleLazyObject: <django.contrib.auth.models.AnonymousUser object at 0x7f9e48fd1f40>>, 'perms': <django.contrib.auth.context_processors.PermWrapper object at 0x7f9e48fd10a0>, 'messages': <django.contrib.messages.storage.fallback.FallbackStorage object at 0x7f9e48fce910>, 'DEFAULT_MESSAGE_LEVELS': {'DEBUG': 10, 'INFO': 20, 'SUCCESS': 25, 'WARNING': 30, 'ERROR': 40}}, {}, {'form': <RegisterForm bound=False, valid=False, fields=(first_name;last_name;email;password1;password2)>, 'view': <accounts.views.RegisterView object at 0x7f9e48fcea00>}]
Exception while resolving variable 'cart_items' in template 'accounts/login.html'.
Traceback (most recent call last):
  File "/home/ubuntu/stringkeeper/lib/python3.8/site-packages/django/template/base.py", line 829, in _resolve_lookup
    current = current[bit]
  File "/home/ubuntu/stringkeeper/lib/python3.8/site-packages/django/contrib/sessions/backends/base.py", line 54, in __getitem__
    return self._session[key]
KeyError: 'cart_items'

During handling of the above exception, another exception occurred:

Traceback (most recent call last):
  File "/home/ubuntu/stringkeeper/lib/python3.8/site-packages/django/template/base.py", line 837, in _resolve_lookup
    current = getattr(current, bit)
AttributeError: 'SessionStore' object has no attribute 'cart_items'

During handling of the above exception, another exception occurred:

Traceback (most recent call last):
  File "/home/ubuntu/stringkeeper/lib/python3.8/site-packages/django/template/base.py", line 843, in _resolve_lookup
    current = current[int(bit)]
ValueError: invalid literal for int() with base 10: 'cart_items'

During handling of the above exception, another exception occurred:

Traceback (most recent call last):
  File "/home/ubuntu/stringkeeper/lib/python3.8/site-packages/django/template/base.py", line 848, in _resolve_lookup
    raise VariableDoesNotExist("Failed lookup for key "
django.template.base.VariableDoesNotExist: Failed lookup for key [cart_items] in <django.contrib.sessions.backends.db.SessionStore object at 0x7f9e48c60e80>
Exception while resolving variable 'q' in template 'accounts/login.html'.
Traceback (most recent call last):
  File "/home/ubuntu/stringkeeper/lib/python3.8/site-packages/django/utils/datastructures.py", line 78, in __getitem__
    list_ = super().__getitem__(key)
KeyError: 'q'

During handling of the above exception, another exception occurred:

Traceback (most recent call last):
  File "/home/ubuntu/stringkeeper/lib/python3.8/site-packages/django/template/base.py", line 829, in _resolve_lookup
    current = current[bit]
  File "/home/ubuntu/stringkeeper/lib/python3.8/site-packages/django/utils/datastructures.py", line 80, in __getitem__
    raise MultiValueDictKeyError(key)
django.utils.datastructures.MultiValueDictKeyError: 'q'

During handling of the above exception, another exception occurred:

Traceback (most recent call last):
  File "/home/ubuntu/stringkeeper/lib/python3.8/site-packages/django/template/base.py", line 837, in _resolve_lookup
    current = getattr(current, bit)
AttributeError: 'QueryDict' object has no attribute 'q'

During handling of the above exception, another exception occurred:

Traceback (most recent call last):
  File "/home/ubuntu/stringkeeper/lib/python3.8/site-packages/django/template/base.py", line 843, in _resolve_lookup
    current = current[int(bit)]
ValueError: invalid literal for int() with base 10: 'q'

During handling of the above exception, another exception occurred:

Traceback (most recent call last):
  File "/home/ubuntu/stringkeeper/lib/python3.8/site-packages/django/template/base.py", line 848, in _resolve_lookup
    raise VariableDoesNotExist("Failed lookup for key "
django.template.base.VariableDoesNotExist: Failed lookup for key [q] in <QueryDict: {}>
Exception while resolving variable 'ascii_art' in template 'accounts/login.html'.
Traceback (most recent call last):
  File "/home/ubuntu/stringkeeper/lib/python3.8/site-packages/django/template/base.py", line 829, in _resolve_lookup
    current = current[bit]
  File "/home/ubuntu/stringkeeper/lib/python3.8/site-packages/django/template/context.py", line 83, in __getitem__
    raise KeyError(key)
KeyError: 'ascii_art'

During handling of the above exception, another exception occurred:

Traceback (most recent call last):
  File "/home/ubuntu/stringkeeper/lib/python3.8/site-packages/django/template/base.py", line 835, in _resolve_lookup
    if isinstance(current, BaseContext) and getattr(type(current), bit):
AttributeError: type object 'RequestContext' has no attribute 'ascii_art'

During handling of the above exception, another exception occurred:

Traceback (most recent call last):
  File "/home/ubuntu/stringkeeper/lib/python3.8/site-packages/django/template/base.py", line 843, in _resolve_lookup
    current = current[int(bit)]
ValueError: invalid literal for int() with base 10: 'ascii_art'

During handling of the above exception, another exception occurred:

Traceback (most recent call last):
  File "/home/ubuntu/stringkeeper/lib/python3.8/site-packages/django/template/base.py", line 848, in _resolve_lookup
    raise VariableDoesNotExist("Failed lookup for key "
django.template.base.VariableDoesNotExist: Failed lookup for key [ascii_art] in [{'True': True, 'False': False, 'None': None}, {'csrf_token': <SimpleLazyObject: 'mYoWXHX9X0OqZvYICDu5Ml6NB3SHMBqIknaubObrrNT8rtNqIO3N9M7kDK3PjlKk'>, 'request': <WSGIRequest: GET '/login/'>, 'user': <SimpleLazyObject: <django.contrib.auth.models.AnonymousUser object at 0x7f9e48be6f40>>, 'perms': <django.contrib.auth.context_processors.PermWrapper object at 0x7f9e48be64c0>, 'messages': <django.contrib.messages.storage.fallback.FallbackStorage object at 0x7f9e48c60ee0>, 'DEFAULT_MESSAGE_LEVELS': {'DEBUG': 10, 'INFO': 20, 'SUCCESS': 25, 'WARNING': 30, 'ERROR': 40}}, {}, {'form': <LoginForm bound=False, valid=False, fields=(email;password)>, 'view': <accounts.views.LoginView object at 0x7f9e48c60f10>}]
Exception while resolving variable 'cart_items' in template 'home.html'.
Traceback (most recent call last):
  File "/home/ubuntu/stringkeeper/lib/python3.8/site-packages/django/template/base.py", line 829, in _resolve_lookup
    current = current[bit]
  File "/home/ubuntu/stringkeeper/lib/python3.8/site-packages/django/contrib/sessions/backends/base.py", line 54, in __getitem__
    return self._session[key]
KeyError: 'cart_items'

During handling of the above exception, another exception occurred:

Traceback (most recent call last):
  File "/home/ubuntu/stringkeeper/lib/python3.8/site-packages/django/template/base.py", line 837, in _resolve_lookup
    current = getattr(current, bit)
AttributeError: 'SessionStore' object has no attribute 'cart_items'

During handling of the above exception, another exception occurred:

Traceback (most recent call last):
  File "/home/ubuntu/stringkeeper/lib/python3.8/site-packages/django/template/base.py", line 843, in _resolve_lookup
    current = current[int(bit)]
ValueError: invalid literal for int() with base 10: 'cart_items'

During handling of the above exception, another exception occurred:

Traceback (most recent call last):
  File "/home/ubuntu/stringkeeper/lib/python3.8/site-packages/django/template/base.py", line 848, in _resolve_lookup
    raise VariableDoesNotExist("Failed lookup for key "
django.template.base.VariableDoesNotExist: Failed lookup for key [cart_items] in <django.contrib.sessions.backends.db.SessionStore object at 0x7f9e48be62e0>
Exception while resolving variable 'q' in template 'home.html'.
Traceback (most recent call last):
  File "/home/ubuntu/stringkeeper/lib/python3.8/site-packages/django/utils/datastructures.py", line 78, in __getitem__
    list_ = super().__getitem__(key)
KeyError: 'q'

During handling of the above exception, another exception occurred:

Traceback (most recent call last):
  File "/home/ubuntu/stringkeeper/lib/python3.8/site-packages/django/template/base.py", line 829, in _resolve_lookup
    current = current[bit]
  File "/home/ubuntu/stringkeeper/lib/python3.8/site-packages/django/utils/datastructures.py", line 80, in __getitem__
    raise MultiValueDictKeyError(key)
django.utils.datastructures.MultiValueDictKeyError: 'q'

During handling of the above exception, another exception occurred:

Traceback (most recent call last):
  File "/home/ubuntu/stringkeeper/lib/python3.8/site-packages/django/template/base.py", line 837, in _resolve_lookup
    current = getattr(current, bit)
AttributeError: 'QueryDict' object has no attribute 'q'

During handling of the above exception, another exception occurred:

Traceback (most recent call last):
  File "/home/ubuntu/stringkeeper/lib/python3.8/site-packages/django/template/base.py", line 843, in _resolve_lookup
    current = current[int(bit)]
ValueError: invalid literal for int() with base 10: 'q'

During handling of the above exception, another exception occurred:

Traceback (most recent call last):
  File "/home/ubuntu/stringkeeper/lib/python3.8/site-packages/django/template/base.py", line 848, in _resolve_lookup
    raise VariableDoesNotExist("Failed lookup for key "
django.template.base.VariableDoesNotExist: Failed lookup for key [q] in <QueryDict: {}>
